Failure # 1 (occurred at 2025-08-13_09-57-12)
[36mray::ImplicitFunc.train()[39m (pid=29904, ip=127.0.0.1, actor_id=8f70e51a06dc09c0a1712f1601000000, repr=train_model)
  File "python\\ray\\_raylet.pyx", line 1925, in ray._raylet.execute_task
  File "python\\ray\\_raylet.pyx", line 1865, in ray._raylet.execute_task.function_executor
  File "C:\Users\santi\Desktop\Proyectos\Fashion-PyTorch\dep\lib\site-packages\ray\_private\function_manager.py", line 689, in actor_method_executor
    return method(__ray_actor, *args, **kwargs)
  File "C:\Users\santi\Desktop\Proyectos\Fashion-PyTorch\dep\lib\site-packages\ray\util\tracing\tracing_helper.py", line 461, in _resume_span
    return method(self, *_args, **_kwargs)
  File "C:\Users\santi\Desktop\Proyectos\Fashion-PyTorch\dep\lib\site-packages\ray\tune\trainable\trainable.py", line 331, in train
    raise skipped from exception_cause(skipped)
  File "C:\Users\santi\Desktop\Proyectos\Fashion-PyTorch\dep\lib\site-packages\ray\air\_internal\util.py", line 107, in run
    self._ret = self._target(*self._args, **self._kwargs)
  File "C:\Users\santi\Desktop\Proyectos\Fashion-PyTorch\dep\lib\site-packages\ray\tune\trainable\function_trainable.py", line 45, in <lambda>
    training_func=lambda: self._trainable_func(self.config),
  File "C:\Users\santi\Desktop\Proyectos\Fashion-PyTorch\dep\lib\site-packages\ray\util\tracing\tracing_helper.py", line 461, in _resume_span
    return method(self, *_args, **_kwargs)
  File "C:\Users\santi\Desktop\Proyectos\Fashion-PyTorch\dep\lib\site-packages\ray\tune\trainable\function_trainable.py", line 261, in _trainable_func
    output = fn()
  File "C:\Users\santi\Desktop\Proyectos\Fashion-PyTorch\dep\lib\site-packages\ray\tune\trainable\util.py", line 130, in inner
    return trainable(config, **fn_kwargs)
  File "C:\Users\santi\Desktop\Proyectos\Fashion-PyTorch\utils\train_model.py", line 45, in train_model
    tune.report({"accuracy": correct_val_samples.mean()})
AttributeError: 'list' object has no attribute 'mean'
